Traceback (most recent call last):
  File "/Users/michaeladams/.pyenv/versions/3.9.7/lib/python3.9/site-packages/jupyter_cache/executors/utils.py", line 58, in single_nb_execution
    executenb(
  File "/Users/michaeladams/.pyenv/versions/3.9.7/lib/python3.9/site-packages/nbclient/client.py", line 1305, in execute
    return NotebookClient(nb=nb, resources=resources, km=km, **kwargs).execute()
  File "/Users/michaeladams/.pyenv/versions/3.9.7/lib/python3.9/site-packages/jupyter_core/utils/__init__.py", line 166, in wrapped
    return loop.run_until_complete(inner)
  File "/Users/michaeladams/.pyenv/versions/3.9.7/lib/python3.9/asyncio/base_events.py", line 642, in run_until_complete
    return future.result()
  File "/Users/michaeladams/.pyenv/versions/3.9.7/lib/python3.9/site-packages/nbclient/client.py", line 705, in async_execute
    await self.async_execute_cell(
  File "/Users/michaeladams/.pyenv/versions/3.9.7/lib/python3.9/site-packages/nbclient/client.py", line 1058, in async_execute_cell
    await self._check_raise_for_error(cell, cell_index, exec_reply)
  File "/Users/michaeladams/.pyenv/versions/3.9.7/lib/python3.9/site-packages/nbclient/client.py", line 914, in _check_raise_for_error
    raise CellExecutionError.from_cell_and_msg(cell, exec_reply_content)
nbclient.exceptions.CellExecutionError: An error occurred while executing the following cell:
------------------
from datachef import acquire, preview, CsvSelectable

table: CsvSelectable = acquire.csv.http("https://raw.githubusercontent.com/mikeAdamss/datachef/main/tests/fixtures/csv/bands-wide.csv")

# Select them
selection = (table.excel_ref('C') | table.excel_ref('D')).is_not_blank()

# Preview the selection - PRIOR to validation
# note - for the sake of this example, you'd just do it in one typically
preview(selection)

# Noe validate it
numeric_validator = NumericValidator()
selection.validate(numeric_validator)

------------------


[0;31m---------------------------------------------------------------------------[0m
[0;31mCellValidationError[0m                       Traceback (most recent call last)
Cell [0;32mIn[5], line 14[0m
[1;32m     12[0m [38;5;66;03m# Noe validate it[39;00m
[1;32m     13[0m numeric_validator [38;5;241m=[39m NumericValidator()
[0;32m---> 14[0m [43mselection[49m[38;5;241;43m.[39;49m[43mvalidate[49m[43m([49m[43mnumeric_validator[49m[43m)[49m

File [0;32m~/.pyenv/versions/3.9.7/lib/python3.9/site-packages/datachef/selection/selectable.py:355[0m, in [0;36mSelectable.validate[0;34m(self, validator, raise_first_error)[0m
[1;32m    352[0m             validation_errors[38;5;241m.[39mappend(validator[38;5;241m.[39mmsg(cell))
[1;32m    354[0m [38;5;28;01mif[39;00m [38;5;28mlen[39m(validation_errors) [38;5;241m>[39m [38;5;241m0[39m:
[0;32m--> 355[0m     [38;5;28;01mraise[39;00m CellValidationError([38;5;124mf[39m[38;5;124m"[39m[38;5;132;01m{[39;00mlinesep[38;5;132;01m}[39;00m[38;5;124m"[39m[38;5;241m.[39mjoin(validation_errors))
[1;32m    357[0m [38;5;28;01mreturn[39;00m [38;5;28mself[39m

[0;31mCellValidationError[0m: "Houses" is not numeric
"Cars" is not numeric

