Traceback (most recent call last):
  File "/home/user/.pyenv/versions/3.12.11/lib/python3.12/site-packages/jupyter_core/utils/__init__.py", line 154, in wrapped
    asyncio.get_running_loop()
RuntimeError: no running event loop

During handling of the above exception, another exception occurred:

Traceback (most recent call last):
  File "/home/user/.pyenv/versions/3.12.11/lib/python3.12/site-packages/jupyter_cache/executors/utils.py", line 58, in single_nb_execution
    executenb(
  File "/home/user/.pyenv/versions/3.12.11/lib/python3.12/site-packages/nbclient/client.py", line 1319, in execute
    return NotebookClient(nb=nb, resources=resources, km=km, **kwargs).execute()
           ^^^^^^^^^^^^^^^^^^^^^^^^^^^^^^^^^^^^^^^^^^^^^^^^^^^^^^^^^^^^^^^^^^^^^
  File "/home/user/.pyenv/versions/3.12.11/lib/python3.12/site-packages/jupyter_core/utils/__init__.py", line 158, in wrapped
    return loop.run_until_complete(inner)
           ^^^^^^^^^^^^^^^^^^^^^^^^^^^^^^
  File "/home/user/.pyenv/versions/3.12.11/lib/python3.12/asyncio/base_events.py", line 691, in run_until_complete
    return future.result()
           ^^^^^^^^^^^^^^^
  File "/home/user/.pyenv/versions/3.12.11/lib/python3.12/site-packages/nbclient/client.py", line 709, in async_execute
    await self.async_execute_cell(
  File "/home/user/.pyenv/versions/3.12.11/lib/python3.12/site-packages/nbclient/client.py", line 1062, in async_execute_cell
    await self._check_raise_for_error(cell, cell_index, exec_reply)
  File "/home/user/.pyenv/versions/3.12.11/lib/python3.12/site-packages/nbclient/client.py", line 918, in _check_raise_for_error
    raise CellExecutionError.from_cell_and_msg(cell, exec_reply_content)
nbclient.exceptions.CellExecutionError: An error occurred while executing the following cell:
------------------
from tidychef import acquire, preview
from tidychef.selection import CsvSelectable

table: CsvSelectable = acquire.csv.http("https://raw.githubusercontent.com/mikeAdamss/tidychef/main/tests/fixtures/csv/bands-wide.csv")

# Select them
selection = (table.excel_ref('C') | table.excel_ref('D')).is_not_blank()

# Preview the selection - PRIOR to validation
# note - for the sake of this example, you'd just do it in one typically
preview(selection)

# Noe validate it
numeric_validator = NumericValidator()
selection.validate(numeric_validator)

------------------


[31m---------------------------------------------------------------------------[39m
[31mCellValidationError[39m                       Traceback (most recent call last)
[36mCell[39m[36m [39m[32mIn[4][39m[32m, line 15[39m
[32m     13[39m [38;5;66;03m# Noe validate it[39;00m
[32m     14[39m numeric_validator = NumericValidator()
[32m---> [39m[32m15[39m [43mselection[49m[43m.[49m[43mvalidate[49m[43m([49m[43mnumeric_validator[49m[43m)[49m

[36mFile [39m[32m~/.pyenv/versions/3.12.11/lib/python3.12/site-packages/tidychef/selection/selectable.py:468[39m, in [36mSelectable.validate[39m[34m(self, validator, raise_first_error)[39m
[32m    465[39m                     validation_errors.append(validator.msg(cell))
[32m    467[39m         [38;5;28;01mif[39;00m [38;5;28mlen[39m(validation_errors) > [32m0[39m:
[32m--> [39m[32m468[39m             [38;5;28;01mraise[39;00m CellValidationError(
[32m    469[39m                 [33mf[39m[33m"""[39m
[32m    470[39m [33mWhen making selections from table: [39m[38;5;132;01m{[39;00m[38;5;28mself[39m.name[38;5;132;01m}[39;00m[33m the[39m
[32m    471[39m [33mfollowing validation errors were encountered:[39m
[32m    472[39m [38;5;132;01m{[39;00mlinesep.join(validation_errors)[38;5;132;01m}[39;00m
[32m    473[39m [33m                [39m[33m"""[39m
[32m    474[39m             )
[32m    476[39m         [38;5;28;01mreturn[39;00m [38;5;28mself[39m

[31mCellValidationError[39m: 
When making selections from table: Unnamed Table the
following validation errors were encountered:
"Houses" is not numeric
"Cars" is not numeric
                

