Traceback (most recent call last):
  File "/home/user/.pyenv/versions/3.12.11/lib/python3.12/site-packages/jupyter_core/utils/__init__.py", line 154, in wrapped
    asyncio.get_running_loop()
RuntimeError: no running event loop

During handling of the above exception, another exception occurred:

Traceback (most recent call last):
  File "/home/user/.pyenv/versions/3.12.11/lib/python3.12/site-packages/jupyter_cache/executors/utils.py", line 58, in single_nb_execution
    executenb(
  File "/home/user/.pyenv/versions/3.12.11/lib/python3.12/site-packages/nbclient/client.py", line 1319, in execute
    return NotebookClient(nb=nb, resources=resources, km=km, **kwargs).execute()
           ^^^^^^^^^^^^^^^^^^^^^^^^^^^^^^^^^^^^^^^^^^^^^^^^^^^^^^^^^^^^^^^^^^^^^
  File "/home/user/.pyenv/versions/3.12.11/lib/python3.12/site-packages/jupyter_core/utils/__init__.py", line 158, in wrapped
    return loop.run_until_complete(inner)
           ^^^^^^^^^^^^^^^^^^^^^^^^^^^^^^
  File "/home/user/.pyenv/versions/3.12.11/lib/python3.12/asyncio/base_events.py", line 691, in run_until_complete
    return future.result()
           ^^^^^^^^^^^^^^^
  File "/home/user/.pyenv/versions/3.12.11/lib/python3.12/site-packages/nbclient/client.py", line 709, in async_execute
    await self.async_execute_cell(
  File "/home/user/.pyenv/versions/3.12.11/lib/python3.12/site-packages/nbclient/client.py", line 1062, in async_execute_cell
    await self._check_raise_for_error(cell, cell_index, exec_reply)
  File "/home/user/.pyenv/versions/3.12.11/lib/python3.12/site-packages/nbclient/client.py", line 918, in _check_raise_for_error
    raise CellExecutionError.from_cell_and_msg(cell, exec_reply_content)
nbclient.exceptions.CellExecutionError: An error occurred while executing the following cell:
------------------
# Now we try and concatenate them - and get an error!

tidydata1 + tidydata2
------------------


[31m---------------------------------------------------------------------------[39m
[31mMisalignedHeadersError[39m                    Traceback (most recent call last)
[36mCell[39m[36m [39m[32mIn[9][39m[32m, line 3[39m
[32m      1[39m [38;5;66;03m# Now we try and concatenate them - and get an error![39;00m
[32m----> [39m[32m3[39m [43mtidydata1[49m[43m [49m[43m+[49m[43m [49m[43mtidydata2[49m

[36mFile [39m[32m~/.pyenv/versions/3.12.11/lib/python3.12/site-packages/tidychef/utils/decorators/dontmutate.py:24[39m, in [36mdontmutate.<locals>.wrapper[39m[34m(self, *args, **kwargs)[39m
[32m     21[39m [38;5;129m@wraps[39m(method)
[32m     22[39m [38;5;28;01mdef[39;00m[38;5;250m [39m[34mwrapper[39m([38;5;28mself[39m, *args, **kwargs):
[32m     23[39m     [38;5;28mself[39m = copy.deepcopy([38;5;28mself[39m)
[32m---> [39m[32m24[39m     [38;5;28;01mreturn[39;00m [43mmethod[49m[43m([49m[38;5;28;43mself[39;49m[43m,[49m[43m [49m[43m*[49m[43margs[49m[43m,[49m[43m [49m[43m*[49m[43m*[49m[43mkwargs[49m[43m)[49m

[36mFile [39m[32m~/.pyenv/versions/3.12.11/lib/python3.12/site-packages/tidychef/output/tidydata.py:197[39m, in [36mTidyData.__add__[39m[34m(self, other_tidy_data)[39m
[32m    194[39m [38;5;66;03m# Error if we're joining two TidyData objects[39;00m
[32m    195[39m [38;5;66;03m# with different headers[39;00m
[32m    196[39m [38;5;28;01mif[39;00m [38;5;28mself[39m._data[[32m0[39m] != other_tidy_data._data[[32m0[39m]:
[32m--> [39m[32m197[39m     [38;5;28;01mraise[39;00m MisalignedHeadersError(
[32m    198[39m         [33mf[39m[33m"""[39m
[32m    199[39m [33m        You are attempting to sum two tidy data[39m
[32m    200[39m [33m        outputs but they do not have the same[39m
[32m    201[39m [33m        column headers.[39m
[32m    202[39m 
[32m    203[39m [33m        TidyData1 headers:[39m
[32m    204[39m [33m        [39m[38;5;132;01m{[39;00m[38;5;28mself[39m._data[[32m0[39m][38;5;132;01m}[39;00m
[32m    205[39m 
[32m    206[39m [33m        TidyData2 headers:[39m
[32m    207[39m [33m        [39m[38;5;132;01m{[39;00mother_tidy_data._data[[32m0[39m][38;5;132;01m}[39;00m
[32m    208[39m [33m    [39m[33m"""[39m
[32m    209[39m     )
[32m    211[39m [38;5;66;03m# Since the headers match, join all but the header[39;00m
[32m    212[39m [38;5;66;03m# row from the new source[39;00m
[32m    213[39m [38;5;28mself[39m._data += other_tidy_data._data[[32m1[39m:]

[31mMisalignedHeadersError[39m: 
                You are attempting to sum two tidy data
                outputs but they do not have the same
                column headers.

                TidyData1 headers:
                [(VIRTUAL CELL, value:"Observations"), (VIRTUAL CELL, value:"Period"), (VIRTUAL CELL, value:"Dataset Identifier Code"), (VIRTUAL CELL, value:"Houses")]

                TidyData2 headers:
                [(VIRTUAL CELL, value:"Value"), (VIRTUAL CELL, value:"Period"), (VIRTUAL CELL, value:"Dataset Identifier Code"), (VIRTUAL CELL, value:"Houses")]
            

