Traceback (most recent call last):
  File "/home/user/.pyenv/versions/3.12.11/lib/python3.12/site-packages/jupyter_core/utils/__init__.py", line 154, in wrapped
    asyncio.get_running_loop()
RuntimeError: no running event loop

During handling of the above exception, another exception occurred:

Traceback (most recent call last):
  File "/home/user/.pyenv/versions/3.12.11/lib/python3.12/site-packages/jupyter_cache/executors/utils.py", line 58, in single_nb_execution
    executenb(
  File "/home/user/.pyenv/versions/3.12.11/lib/python3.12/site-packages/nbclient/client.py", line 1319, in execute
    return NotebookClient(nb=nb, resources=resources, km=km, **kwargs).execute()
           ^^^^^^^^^^^^^^^^^^^^^^^^^^^^^^^^^^^^^^^^^^^^^^^^^^^^^^^^^^^^^^^^^^^^^
  File "/home/user/.pyenv/versions/3.12.11/lib/python3.12/site-packages/jupyter_core/utils/__init__.py", line 158, in wrapped
    return loop.run_until_complete(inner)
           ^^^^^^^^^^^^^^^^^^^^^^^^^^^^^^
  File "/home/user/.pyenv/versions/3.12.11/lib/python3.12/asyncio/base_events.py", line 691, in run_until_complete
    return future.result()
           ^^^^^^^^^^^^^^^
  File "/home/user/.pyenv/versions/3.12.11/lib/python3.12/site-packages/nbclient/client.py", line 709, in async_execute
    await self.async_execute_cell(
  File "/home/user/.pyenv/versions/3.12.11/lib/python3.12/site-packages/nbclient/client.py", line 1062, in async_execute_cell
    await self._check_raise_for_error(cell, cell_index, exec_reply)
  File "/home/user/.pyenv/versions/3.12.11/lib/python3.12/site-packages/nbclient/client.py", line 918, in _check_raise_for_error
    raise CellExecutionError.from_cell_and_msg(cell, exec_reply_content)
nbclient.exceptions.CellExecutionError: An error occurred while executing the following cell:
------------------
from tidychef import acquire, against
from tidychef.direction import right, down
from tidychef.output import TidyData, Column
from tidychef.selection import XlsxSelectable

table: XlsxSelectable = acquire.xlsx.http("https://github.com/mikeAdamss/tidychef/raw/main/tests/fixtures/xlsx/ons-oic.xlsx", tables="Table 3c")

observations = table.excel_ref("B7:H10").label_as("Observations")
dataset_identifier_code = table.excel_ref("B6").expand(right).label_as("Dataset Identifier Codes")

# Note: matches a regex of capital M followed by anything
tidy_data = TidyData(
    observations,
    Column(dataset_identifier_code.finds_observations_directly(down), validate=against.regex("L.*"))
)

print(tidy_data)
------------------


[31m---------------------------------------------------------------------------[39m
[31mAttributeError[39m                            Traceback (most recent call last)
[36mCell[39m[36m [39m[32mIn[2][39m[32m, line 14[39m
[32m      9[39m dataset_identifier_code = table.excel_ref([33m"[39m[33mB6[39m[33m"[39m).expand(right).label_as([33m"[39m[33mDataset Identifier Codes[39m[33m"[39m)
[32m     11[39m [38;5;66;03m# Note: matches a regex of capital M followed by anything[39;00m
[32m     12[39m tidy_data = TidyData(
[32m     13[39m     observations,
[32m---> [39m[32m14[39m     Column([43mdataset_identifier_code[49m[43m.[49m[43mfinds_observations_directly[49m(down), validate=against.regex([33m"[39m[33mL.*[39m[33m"[39m))
[32m     15[39m )
[32m     17[39m [38;5;28mprint[39m(tidy_data)

[31mAttributeError[39m: 'XlsxSelectable' object has no attribute 'finds_observations_directly'

