Traceback (most recent call last):
  File "/home/user/.pyenv/versions/3.12.11/lib/python3.12/site-packages/jupyter_core/utils/__init__.py", line 154, in wrapped
    asyncio.get_running_loop()
RuntimeError: no running event loop

During handling of the above exception, another exception occurred:

Traceback (most recent call last):
  File "/home/user/.pyenv/versions/3.12.11/lib/python3.12/site-packages/jupyter_cache/executors/utils.py", line 58, in single_nb_execution
    executenb(
  File "/home/user/.pyenv/versions/3.12.11/lib/python3.12/site-packages/nbclient/client.py", line 1319, in execute
    return NotebookClient(nb=nb, resources=resources, km=km, **kwargs).execute()
           ^^^^^^^^^^^^^^^^^^^^^^^^^^^^^^^^^^^^^^^^^^^^^^^^^^^^^^^^^^^^^^^^^^^^^
  File "/home/user/.pyenv/versions/3.12.11/lib/python3.12/site-packages/jupyter_core/utils/__init__.py", line 158, in wrapped
    return loop.run_until_complete(inner)
           ^^^^^^^^^^^^^^^^^^^^^^^^^^^^^^
  File "/home/user/.pyenv/versions/3.12.11/lib/python3.12/asyncio/base_events.py", line 691, in run_until_complete
    return future.result()
           ^^^^^^^^^^^^^^^
  File "/home/user/.pyenv/versions/3.12.11/lib/python3.12/site-packages/nbclient/client.py", line 709, in async_execute
    await self.async_execute_cell(
  File "/home/user/.pyenv/versions/3.12.11/lib/python3.12/site-packages/nbclient/client.py", line 1062, in async_execute_cell
    await self._check_raise_for_error(cell, cell_index, exec_reply)
  File "/home/user/.pyenv/versions/3.12.11/lib/python3.12/site-packages/nbclient/client.py", line 918, in _check_raise_for_error
    raise CellExecutionError.from_cell_and_msg(cell, exec_reply_content)
nbclient.exceptions.CellExecutionError: An error occurred while executing the following cell:
------------------
observations = table.filter(filters.is_numeric).label_as("Observations")
sex = table.excel_ref("1").is_not_blank().label_as("Sex")
preview(observations, sex)

tidy_data = TidyData(
    observations,
    Column(sex.finds_observations_within(down, start=right(1), end=left(1)))
)

print(tidy_data)

------------------


[31m---------------------------------------------------------------------------[39m
[31mAttributeError[39m                            Traceback (most recent call last)
[36mCell[39m[36m [39m[32mIn[4][39m[32m, line 7[39m
[32m      2[39m sex = table.excel_ref([33m"[39m[33m1[39m[33m"[39m).is_not_blank().label_as([33m"[39m[33mSex[39m[33m"[39m)
[32m      3[39m preview(observations, sex)
[32m      5[39m tidy_data = TidyData(
[32m      6[39m     observations,
[32m----> [39m[32m7[39m     Column([43msex[49m[43m.[49m[43mfinds_observations_within[49m(down, start=right([32m1[39m), end=left([32m1[39m)))
[32m      8[39m )
[32m     10[39m [38;5;28mprint[39m(tidy_data)

[31mAttributeError[39m: 'Selectable' object has no attribute 'finds_observations_within'

