Traceback (most recent call last):
  File "/Users/michaeladams/.local/share/virtualenvs/trypandas-_I_Hh2lX/lib/python3.10/site-packages/jupyter_cache/executors/utils.py", line 58, in single_nb_execution
    executenb(
  File "/Users/michaeladams/.local/share/virtualenvs/trypandas-_I_Hh2lX/lib/python3.10/site-packages/nbclient/client.py", line 1204, in execute
    return NotebookClient(nb=nb, resources=resources, km=km, **kwargs).execute()
  File "/Users/michaeladams/.local/share/virtualenvs/trypandas-_I_Hh2lX/lib/python3.10/site-packages/nbclient/util.py", line 84, in wrapped
    return just_run(coro(*args, **kwargs))
  File "/Users/michaeladams/.local/share/virtualenvs/trypandas-_I_Hh2lX/lib/python3.10/site-packages/nbclient/util.py", line 62, in just_run
    return loop.run_until_complete(coro)
  File "/Users/michaeladams/.pyenv/versions/3.10.6/lib/python3.10/asyncio/base_events.py", line 646, in run_until_complete
    return future.result()
  File "/Users/michaeladams/.local/share/virtualenvs/trypandas-_I_Hh2lX/lib/python3.10/site-packages/nbclient/client.py", line 663, in async_execute
    await self.async_execute_cell(
  File "/Users/michaeladams/.local/share/virtualenvs/trypandas-_I_Hh2lX/lib/python3.10/site-packages/nbclient/client.py", line 965, in async_execute_cell
    await self._check_raise_for_error(cell, cell_index, exec_reply)
  File "/Users/michaeladams/.local/share/virtualenvs/trypandas-_I_Hh2lX/lib/python3.10/site-packages/nbclient/client.py", line 862, in _check_raise_for_error
    raise CellExecutionError.from_cell_and_msg(cell, exec_reply_content)
nbclient.exceptions.CellExecutionError: An error occurred while executing the following cell:
------------------
from typing import List
from datachef import acquire
from datachef.selection import XlsxSelectable

tables: List[XlsxSelectable] = acquire.xlsx.http("https://github.com/mikeAdamss/datachef/raw/main/tests/fixtures/xlsx/ons-oic.xlsx")
tables[7].excel_ref('A1:A2').assert_one()
------------------

[0;31m---------------------------------------------------------------------------[0m
[0;31mAssertionError[0m                            Traceback (most recent call last)
[0;32m/var/folders/3q/wpcx20553xv0hpsjgtq_zl_m0000gp/T/ipykernel_34995/1822173736.py[0m in [0;36m<cell line: 6>[0;34m()[0m
[1;32m      4[0m [0;34m[0m[0m
[1;32m      5[0m [0mtables[0m[0;34m:[0m [0mList[0m[0;34m[[0m[0mXlsxSelectable[0m[0;34m][0m [0;34m=[0m [0macquire[0m[0;34m.[0m[0mxlsx[0m[0;34m.[0m[0mhttp[0m[0;34m([0m[0;34m"https://github.com/mikeAdamss/datachef/raw/main/tests/fixtures/xlsx/ons-oic.xlsx"[0m[0;34m)[0m[0;34m[0m[0;34m[0m[0m
[0;32m----> 6[0;31m [0mtables[0m[0;34m[[0m[0;36m7[0m[0;34m][0m[0;34m.[0m[0mexcel_ref[0m[0;34m([0m[0;34m'A1:A2'[0m[0;34m)[0m[0;34m.[0m[0massert_one[0m[0;34m([0m[0;34m)[0m[0;34m[0m[0;34m[0m[0m
[0m
[0;32m~/.local/share/virtualenvs/trypandas-_I_Hh2lX/lib/python3.10/site-packages/datachef/selection/selectable.py[0m in [0;36massert_one[0;34m(self)[0m
[1;32m     61[0m         [0mAssert[0m [0mthat[0m [0mthe[0m [0mcurrent[0m [0mselection[0m [0mcontains[0m [0mexactly[0m [0mone[0m [0mcell[0m[0;34m[0m[0;34m[0m[0m
[1;32m     62[0m         """
[0;32m---> 63[0;31m         assert (
[0m[1;32m     64[0m             [0mlen[0m[0;34m([0m[0mself[0m[0;34m.[0m[0mcells[0m[0;34m)[0m [0;34m==[0m [0;36m1[0m[0;34m[0m[0;34m[0m[0m
[1;32m     65[0m         ), f"Selection contains {len(self.cells)} cells, not 1"

[0;31mAssertionError[0m: Selection contains 2 cells, not 1
AssertionError: Selection contains 2 cells, not 1

