Traceback (most recent call last):
  File "/home/user/.pyenv/versions/3.12.11/lib/python3.12/site-packages/jupyter_core/utils/__init__.py", line 154, in wrapped
    asyncio.get_running_loop()
RuntimeError: no running event loop

During handling of the above exception, another exception occurred:

Traceback (most recent call last):
  File "/home/user/.pyenv/versions/3.12.11/lib/python3.12/site-packages/jupyter_cache/executors/utils.py", line 58, in single_nb_execution
    executenb(
  File "/home/user/.pyenv/versions/3.12.11/lib/python3.12/site-packages/nbclient/client.py", line 1319, in execute
    return NotebookClient(nb=nb, resources=resources, km=km, **kwargs).execute()
           ^^^^^^^^^^^^^^^^^^^^^^^^^^^^^^^^^^^^^^^^^^^^^^^^^^^^^^^^^^^^^^^^^^^^^
  File "/home/user/.pyenv/versions/3.12.11/lib/python3.12/site-packages/jupyter_core/utils/__init__.py", line 158, in wrapped
    return loop.run_until_complete(inner)
           ^^^^^^^^^^^^^^^^^^^^^^^^^^^^^^
  File "/home/user/.pyenv/versions/3.12.11/lib/python3.12/asyncio/base_events.py", line 691, in run_until_complete
    return future.result()
           ^^^^^^^^^^^^^^^
  File "/home/user/.pyenv/versions/3.12.11/lib/python3.12/site-packages/nbclient/client.py", line 709, in async_execute
    await self.async_execute_cell(
  File "/home/user/.pyenv/versions/3.12.11/lib/python3.12/site-packages/nbclient/client.py", line 1062, in async_execute_cell
    await self._check_raise_for_error(cell, cell_index, exec_reply)
  File "/home/user/.pyenv/versions/3.12.11/lib/python3.12/site-packages/nbclient/client.py", line 918, in _check_raise_for_error
    raise CellExecutionError.from_cell_and_msg(cell, exec_reply_content)
nbclient.exceptions.CellExecutionError: An error occurred while executing the following cell:
------------------
from tidychef import acquire, against
from tidychef.selection import CsvSelectable

table: CsvSelectable = acquire.csv.http("https://raw.githubusercontent.com/mikeAdamss/tidychef/main/tests/fixtures/csv/bands-wide.csv")

table.excel_ref('B').is_not_blank().validate(against.regex("John"), raise_first_error=True)
------------------


[31m---------------------------------------------------------------------------[39m
[31mCellValidationError[39m                       Traceback (most recent call last)
[36mCell[39m[36m [39m[32mIn[5][39m[32m, line 6[39m
[32m      2[39m [38;5;28;01mfrom[39;00m[38;5;250m [39m[34;01mtidychef[39;00m[34;01m.[39;00m[34;01mselection[39;00m[38;5;250m [39m[38;5;28;01mimport[39;00m CsvSelectable
[32m      4[39m table: CsvSelectable = acquire.csv.http([33m"[39m[33mhttps://raw.githubusercontent.com/mikeAdamss/tidychef/main/tests/fixtures/csv/bands-wide.csv[39m[33m"[39m)
[32m----> [39m[32m6[39m [43mtable[49m[43m.[49m[43mexcel_ref[49m[43m([49m[33;43m'[39;49m[33;43mB[39;49m[33;43m'[39;49m[43m)[49m[43m.[49m[43mis_not_blank[49m[43m([49m[43m)[49m[43m.[49m[43mvalidate[49m[43m([49m[43magainst[49m[43m.[49m[43mregex[49m[43m([49m[33;43m"[39;49m[33;43mJohn[39;49m[33;43m"[39;49m[43m)[49m[43m,[49m[43m [49m[43mraise_first_error[49m[43m=[49m[38;5;28;43;01mTrue[39;49;00m[43m)[49m

[36mFile [39m[32m~/.pyenv/versions/3.12.11/lib/python3.12/site-packages/tidychef/selection/selectable.py:462[39m, in [36mSelectable.validate[39m[34m(self, validator, raise_first_error)[39m
[32m    460[39m             [38;5;28;01mif[39;00m [38;5;129;01mnot[39;00m validator(cell):
[32m    461[39m                 [38;5;28;01mif[39;00m raise_first_error:
[32m--> [39m[32m462[39m                     [38;5;28;01mraise[39;00m CellValidationError(
[32m    463[39m                         [33mf[39m[33m"""[39m
[32m    464[39m [33mWhen making selections from table: [39m[38;5;132;01m{[39;00m[38;5;28mself[39m.name[38;5;132;01m}[39;00m[33m the[39m
[32m    465[39m [33mfollowing validation error was encountered:[39m
[32m    466[39m [38;5;132;01m{[39;00mvalidator.msg(cell)[38;5;132;01m}[39;00m
[32m    467[39m [33m                [39m[33m"""[39m
[32m    468[39m                     )
[32m    469[39m                 [38;5;28;01melse[39;00m:
[32m    470[39m                     validation_errors.append(validator.msg(cell))

[31mCellValidationError[39m: 
When making selections from table: Unnamed Table the
following validation error was encountered:
"Paul" does not match pattern: "John"
                

