Traceback (most recent call last):
  File "/Users/michaeladams/.pyenv/versions/3.9.7/lib/python3.9/site-packages/jupyter_cache/executors/utils.py", line 58, in single_nb_execution
    executenb(
  File "/Users/michaeladams/.pyenv/versions/3.9.7/lib/python3.9/site-packages/nbclient/client.py", line 1305, in execute
    return NotebookClient(nb=nb, resources=resources, km=km, **kwargs).execute()
  File "/Users/michaeladams/.pyenv/versions/3.9.7/lib/python3.9/site-packages/jupyter_core/utils/__init__.py", line 166, in wrapped
    return loop.run_until_complete(inner)
  File "/Users/michaeladams/.pyenv/versions/3.9.7/lib/python3.9/asyncio/base_events.py", line 642, in run_until_complete
    return future.result()
  File "/Users/michaeladams/.pyenv/versions/3.9.7/lib/python3.9/site-packages/nbclient/client.py", line 705, in async_execute
    await self.async_execute_cell(
  File "/Users/michaeladams/.pyenv/versions/3.9.7/lib/python3.9/site-packages/nbclient/client.py", line 1058, in async_execute_cell
    await self._check_raise_for_error(cell, cell_index, exec_reply)
  File "/Users/michaeladams/.pyenv/versions/3.9.7/lib/python3.9/site-packages/nbclient/client.py", line 914, in _check_raise_for_error
    raise CellExecutionError.from_cell_and_msg(cell, exec_reply_content)
nbclient.exceptions.CellExecutionError: An error occurred while executing the following cell:
------------------
selection.shift(right)
------------------


[0;31m---------------------------------------------------------------------------[0m
[0;31mOutOfBoundsError[0m                          Traceback (most recent call last)
Cell [0;32mIn[6], line 1[0m
[0;32m----> 1[0m [43mselection[49m[38;5;241;43m.[39;49m[43mshift[49m[43m([49m[43mright[49m[43m)[49m

File [0;32m~/.pyenv/versions/3.9.7/lib/python3.9/site-packages/datachef/utils/decorators/dontmutate.py:24[0m, in [0;36mdontmutate.<locals>.wrapper[0;34m(self, *args, **kwargs)[0m
[1;32m     21[0m [38;5;129m@wraps[39m(method)
[1;32m     22[0m [38;5;28;01mdef[39;00m [38;5;21mwrapper[39m([38;5;28mself[39m, [38;5;241m*[39margs, [38;5;241m*[39m[38;5;241m*[39mkwargs):
[1;32m     23[0m     [38;5;28mself[39m [38;5;241m=[39m copy[38;5;241m.[39mdeepcopy([38;5;28mself[39m)
[0;32m---> 24[0m     [38;5;28;01mreturn[39;00m [43mmethod[49m[43m([49m[38;5;28;43mself[39;49m[43m,[49m[43m [49m[38;5;241;43m*[39;49m[43margs[49m[43m,[49m[43m [49m[38;5;241;43m*[39;49m[38;5;241;43m*[39;49m[43mkwargs[49m[43m)[49m

File [0;32m~/.pyenv/versions/3.9.7/lib/python3.9/site-packages/datachef/selection/selectable.py:253[0m, in [0;36mSelectable.shift[0;34m(self, direction_or_x, possibly_y)[0m
[1;32m    250[0m found_cells [38;5;241m=[39m dfc[38;5;241m.[39mmatching_xy_cells([38;5;28mself[39m[38;5;241m.[39mpcells, wanted_cells)
[1;32m    252[0m [38;5;28;01mif[39;00m [38;5;28mlen[39m(found_cells) [38;5;241m==[39m [38;5;241m0[39m [38;5;129;01mand[39;00m [38;5;28mlen[39m(wanted_cells) [38;5;241m>[39m [38;5;241m0[39m:
[0;32m--> 253[0m     [38;5;28;01mraise[39;00m OutOfBoundsError(
[1;32m    254[0m         [38;5;124m"[39m[38;5;124mYou are attempting to shift your selection [39m[38;5;124m"[39m
[1;32m    255[0m         [38;5;124m"[39m[38;5;124mentirely outside of the boundary of the table.[39m[38;5;124m"[39m
[1;32m    256[0m     )
[1;32m    258[0m [38;5;28mself[39m[38;5;241m.[39mcells [38;5;241m=[39m found_cells
[1;32m    259[0m [38;5;28;01mreturn[39;00m [38;5;28mself[39m

[0;31mOutOfBoundsError[0m: You are attempting to shift your selection entirely outside of the boundary of the table.

